<?xml version="1.0"?>
<robot xmlns:xacro="http://www.ros.org/wiki/xacro" name="robot_alpha">

<xacro:include filename="$(find surveillance_robot2)/urdf/robot_alpha.gazebo"/>
<xacro:include filename="$(find surveillance_robot2)/urdf/materials.xacro" />


 <!-- INERTIAL MACROS -->

 <xacro:macro name="cylinder_inertia" params="mass r l"> 
    <inertia ixx="${mass*(3*r*r+l*l)/12}" ixy = "0" ixz = "0"
                iyy="${mass*(3*r*r+l*l)/12}" iyz = "0" izz="${mass*(r*r)/2}" /> 
 </xacro:macro>

 <xacro:macro name="box_inertia" params="mass h d w"> 
    <inertia ixx="${mass*(h*h+d*d)/12}" ixy = "0" ixz = "0"
                iyy="${mass*(h*h+w*w)/12}" iyz = "0" izz="${mass*(d*d+w*w)/12}" /> 
 </xacro:macro>
 
 <xacro:macro name="sphere_inertia" params="mass r"> 
    <inertia ixx="${2*mass*r*r/5}" ixy = "0" ixz = "0"
            iyy="${2*mass*r*r/5}" iyz = "0" izz="${2*mass*r*r/5}" /> 
 </xacro:macro>
 

<!-- CHASSIS -->

  <link name="link_chassis">
    <pose>0 0 0.1 0 0 0</pose>
    <inertial>
      <mass value="10"/>
      <origin rpy="0 0 0" xyz="0 0 0"/>
      <xacro:box_inertia mass="10" h="0.07" d="0.3" w="0.5"/>
    </inertial>
    <collision name="collision_chassis">
      <geometry>
        <box size="0.5 0.3 0.07"/>
      </geometry>
      <origin rpy="0 0 0" xyz="0 0 0"/>
    </collision>
    <visual>
      <origin rpy="0 0 0" xyz="0 0 0"/>
      <geometry>
        <box size="0.5 0.3 0.07"/>
      </geometry>
      <material name="red"/>
    </visual>
  </link>


<!-- WHEELS -->

 <xacro:macro name="link_wheel" params="name">
  <link name="${name}">
    <inertial>
      <mass value="0.2"/>
      <origin rpy="0 1.5707 1.5707" xyz="0 0 0"/>
      <xacro:cylinder_inertia mass="0.2" r="0.1" l="0.04" />
    </inertial>
    <collision name="${name}_collision">
      <origin rpy="0 1.5707 1.5707" xyz="0 0 0"/>
      <geometry>
        <cylinder length="0.04" radius="0.1"/>
      </geometry>
    </collision>
    <visual name="${name}_visual">
      <origin rpy="0 1.5707 1.5707" xyz="0 0 0"/>
      <geometry>
        <cylinder length="0.04" radius="0.1"/>
      </geometry>
      <material name="black"/>
     </visual>
    </link>
  </xacro:macro> 

<xacro:macro name="joint_wheel" params="name child origin_xyz">
  <joint name="${name}" type="continuous">
  <origin rpy="0 0 0" xyz="${origin_xyz}"/>
  <child link="${child}"/>
  <parent link="link_chassis"/>
  <axis rpy="0 0 0" xyz="0 1 0"/>
  <limit effort="10000" velocity="1000"/>
  <joint_properties damping="1.0" friction="1.0"/>
  </joint>
</xacro:macro>


  <xacro:link_wheel name="link_front_right_wheel" />
  <xacro:link_wheel name="link_front_left_wheel" />
  <xacro:link_wheel name="link_back_right_wheel" />
  <xacro:link_wheel name="link_back_left_wheel" />

  <xacro:joint_wheel name="joint_front_right_wheel"  child="link_front_right_wheel"  origin_xyz="0.15 0.15 0"/>
  <xacro:joint_wheel name="joint_front_left_wheel"  child="link_front_left_wheel"  origin_xyz="0.15 -0.15 0"/>
  <xacro:joint_wheel name="joint_back_right_wheel"  child="link_back_right_wheel"  origin_xyz="-0.15 0.15 0"  />
  <xacro:joint_wheel name="joint_back_left_wheel"  child="link_back_left_wheel"  origin_xyz="-0.15 -0.15 0"  />

  <!-- LASERSCAN -->

   <link name="hokuyo_link">
      <collision>
        <origin xyz="0 0 0.035" rpy="0 0 0"/>
        <geometry>
    <box size="0.07 0.07 0.07"/>
        </geometry>
      </collision>
      <visual>
        <origin xyz="0 0 0.035" rpy="0 0 0"/>
        <geometry>
        <box size="0.07 0.07 0.07"/>
        </geometry>
        <material name="grey">
        <color rgba="1 0 0 1"/>
        </material>
      </visual>
      <inertial>
        <mass value="1e-5" />
        <origin xyz="0 0 0.035" rpy="0 0 0"/>
        <inertia ixx="1e-6" ixy="0" ixz="0" iyy="1e-6" iyz="0" izz="1e-6" />
      </inertial> 
   </link>
   
   <joint name="hokuyo_joint" type="fixed">
      <axis xyz="0 1 0" />
      <origin xyz="0.27 0 0.025" rpy="0 0 0"/>
      <parent link="link_chassis"/>
      <child link="hokuyo_link"/> 
   </joint>

<!-- ARM -->
  

  <link name="link_arm_base">
    <inertial>
      <mass value="0.1"/>
      <origin rpy="0 0 0" xyz="0 0 0.015"/>
      <xacro:cylinder_inertia mass="0.1" l="0.05" r="0.1"/>
    </inertial>
    <collision name="link_arm_base_collision">
      <geometry>
        <cylinder length="0.05" radius= "0.1"/>
      </geometry>
      <origin rpy="0 0 0" xyz="0 0 0.015"/>
    </collision>
    <visual>
      <origin rpy="0 0 0" xyz="0 0 0.015"/>
      <geometry>
        <cylinder length="0.05" radius= "0.1"/>
      </geometry>
      <material name="orange"/>
    </visual>
  </link>

  <joint name="joint_arm_base" type="continuous">
    <parent link="link_chassis"/>
    <child link="link_arm_base"/>
    <axis xyz="0 0 1"/>
    <origin xyz="0 0 0.035"/>
  </joint>

  <link name="link_arm1">
    <inertial>
      <mass value="0.002"/>
      <origin rpy="0 0 0" xyz="0 0 0.25"/>
      <xacro:cylinder_inertia mass="0.002" l="0.5" r="0.03"/>
    </inertial>
  <collision name="link_arm1_collision">
      <geometry>
        <cylinder length="0.5" radius= "0.03"/>
      </geometry>
      <origin rpy="0 0 0" xyz="0 0 0.25"/>
    </collision>
    <visual>
      <origin rpy="0 0 0" xyz="0 0 0.25"/>
      <geometry>
        <cylinder length="0.5" radius= "0.03"/>
      </geometry>
      <material name="yellow"/>
    </visual>
  </link>

  <joint name="joint_arm1" type="revolute">
    <parent link="link_arm_base"/>
    <child link="link_arm1"/>
    <axis xyz="0 1 0"/>
    <origin xyz="0 0 0.05"/>
    <limit effort ="100.0" lower="-1.0" upper="1.0" velocity="0.5"/>
  </joint>

  <link name="link_arm2">
    <inertial>
      <mass value="0.002"/>
      <origin rpy="0 0 0" xyz="0 0.06 0.25"/>
      <xacro:cylinder_inertia mass="0.002" l="0.45" r="0.03"/>
    </inertial>
    <collision name="link_arm2_collision">
      <geometry>
        <cylinder length="0.5" radius= "0.03"/>
      </geometry>
      <origin rpy="0 0 0" xyz="0 0.06 0.25"/>
    </collision>
    <visual>
      <origin rpy="0 0 0" xyz="0 0.06 0.25"/>
      <geometry>
        <cylinder length="0.5" radius= "0.03"/>
      </geometry>
      <material name="yellow"/>
    </visual>
  </link>

  <joint name="joint_arm2" type="revolute">
    <parent link="link_arm1"/>
    <child link="link_arm2"/>
    <axis xyz="0 1 0"/>
    <origin xyz="0 0 0.4"/>
    <limit effort ="100.0" lower="-2" upper="2" velocity="0.5"/>
  </joint>

  <!-- CAMERA -->

   <link name="camera_link">
      <collision>
        <origin rpy="0 0 0" xyz="0 0.06 0"/>
        <geometry>
          <sphere radius="0.06"/>
        </geometry>
      </collision>
      <visual>
        <origin rpy="0 0.0 0" xyz="0 0.06 0"/>
        <geometry>
          <sphere radius="0.06"/>
        </geometry>
        <material name="grey">
        <color rgba="1 0 0 1"/>
        </material>
      </visual>
      <inertial>
        <mass value="1e-5" />
        <origin rpy="0 0 0" xyz="0 0.06 0"/>
        <inertia ixx="1e-6" ixy="0" ixz="0" iyy="1e-6" iyz="0" izz="1e-6" />
      </inertial> 
   </link>
   
   <joint name="camera_joint" type="fixed">
      <axis xyz="0 1 0" />
      <origin xyz="0 0 0.56" rpy="0 0 0"/>
      <parent link="link_arm2"/>
      <child link="camera_link"/> 
   </joint>


  <!-- TRASMISSION -->

  <transmission name="joint_arm_base_trans">
    <type>transmission_interface/SimpleTransmission</type>
    <joint name="joint_arm_base">
      <hardwareInterface>hardware_interface/EffortJointInterface</hardwareInterface>
    </joint>
    <actuator name="motor1">
      <hardwareInterface>hardware_interface/EffortJointInterface</hardwareInterface>
      <mechanicalInterface>1</mechanicalInterface>
    </actuator>
  </transmission>

  <transmission name="joint_arm1_trans">
    <type>transmission_interface/SimpleTransmission</type>
    <joint name="joint_arm1">
      <hardwareInterface>hardware_interface/EffortJointInterface</hardwareInterface>
    </joint>
    <actuator name="motor2">
      <hardwareInterface>hardware_interface/EffortJointInterface</hardwareInterface>
      <mechanicalInterface>1</mechanicalInterface>
    </actuator>
  </transmission>

  <transmission name="joint_arm2">
    <type>transmission_interface/SimpleTransmission</type>
    <joint name="joint_arm2">
      <hardwareInterface>hardware_interface/EffortJointInterface</hardwareInterface>
    </joint>
    <actuator name="motor3">
      <hardwareInterface>hardware_interface/EffortJointInterface</hardwareInterface>
      <mechanicalInterface>1</mechanicalInterface>
    </actuator>
  </transmission>


</robot>
